<?xml version="1.0" ?><robot name="yilansimu"><material name="silver"><color rgba="0.700 0.700 0.700 1.000"/></material><transmission name="Revolute 30_tran"><type>transmission_interface/SimpleTransmission</type><joint name="Revolute 30"><hardwareInterface>hardware_interface/EffortJointInterface</hardwareInterface></joint><actuator name="Revolute 30_actr"><hardwareInterface>hardware_interface/EffortJointInterface</hardwareInterface><mechanicalReduction>1</mechanicalReduction></actuator></transmission><transmission name="Revolute 31_tran"><type>transmission_interface/SimpleTransmission</type><joint name="Revolute 31"><hardwareInterface>hardware_interface/EffortJointInterface</hardwareInterface></joint><actuator name="Revolute 31_actr"><hardwareInterface>hardware_interface/EffortJointInterface</hardwareInterface><mechanicalReduction>1</mechanicalReduction></actuator></transmission><transmission name="Revolute 32_tran"><type>transmission_interface/SimpleTransmission</type><joint name="Revolute 32"><hardwareInterface>hardware_interface/EffortJointInterface</hardwareInterface></joint><actuator name="Revolute 32_actr"><hardwareInterface>hardware_interface/EffortJointInterface</hardwareInterface><mechanicalReduction>1</mechanicalReduction></actuator></transmission><transmission name="Revolute 33_tran"><type>transmission_interface/SimpleTransmission</type><joint name="Revolute 33"><hardwareInterface>hardware_interface/EffortJointInterface</hardwareInterface></joint><actuator name="Revolute 33_actr"><hardwareInterface>hardware_interface/EffortJointInterface</hardwareInterface><mechanicalReduction>1</mechanicalReduction></actuator></transmission><gazebo><plugin filename="libgazebo_ros_control.so" name="control"/></gazebo><gazebo reference="base_link"><material>Gazebo/Silver</material><mu1>0.2</mu1><mu2>0.2</mu2><selfCollide>true</selfCollide><gravity>true</gravity></gazebo><gazebo reference="vagon_2_1"><material>Gazebo/Silver</material><mu1>0.2</mu1><mu2>0.2</mu2><selfCollide>true</selfCollide></gazebo><gazebo reference="vagon_3_1"><material>Gazebo/Silver</material><mu1>0.2</mu1><mu2>0.2</mu2><selfCollide>true</selfCollide></gazebo><gazebo reference="vagon_4_1"><material>Gazebo/Silver</material><mu1>0.2</mu1><mu2>0.2</mu2><selfCollide>true</selfCollide></gazebo><gazebo reference="vagon_5_1"><material>Gazebo/Silver</material><mu1>0.2</mu1><mu2>0.2</mu2><selfCollide>true</selfCollide></gazebo><link name="base_link"><inertial><origin rpy="0 0 0" xyz="-0.010140486124849883 4.3371337475389595e-08 1.3412238498127023e-08"/><mass value="0.0045795100400537"/><inertia ixx="0.0" ixy="-0.0" ixz="-0.0" iyy="1e-06" iyz="-0.0" izz="1e-06"/></inertial><visual><origin rpy="0 0 0" xyz="0 0 0"/><geometry><mesh filename="package://yilansimu_description/meshes/base_link.stl" scale="0.001 0.001 0.001"/></geometry><material name="silver"/></visual><collision><origin rpy="0 0 0" xyz="0 0 0"/><geometry><mesh filename="package://yilansimu_description/meshes/base_link.stl" scale="0.001 0.001 0.001"/></geometry></collision></link><link name="vagon_2_1"><inertial><origin rpy="0 0 0" xyz="0.01853454749117604 2.2477804808574556e-08 1.0179807043573104e-08"/><mass value="0.008294307256815443"/><inertia ixx="1e-06" ixy="-0.0" ixz="-0.0" iyy="4e-06" iyz="-0.0" izz="4e-06"/></inertial><visual><origin rpy="0 0 0" xyz="-0.019292 -0.0 -0.0"/><geometry><mesh filename="package://yilansimu_description/meshes/vagon_2_1.stl" scale="0.001 0.001 0.001"/></geometry><material name="silver"/></visual><collision><origin rpy="0 0 0" xyz="-0.019292 -0.0 -0.0"/><geometry><mesh filename="package://yilansimu_description/meshes/vagon_2_1.stl" scale="0.001 0.001 0.001"/></geometry></collision></link><link name="vagon_3_1"><inertial><origin rpy="0 0 0" xyz="0.018534610223486 2.2477804796088586e-08 1.01798070413029e-08"/><mass value="0.008294307256815481"/><inertia ixx="1e-06" ixy="-0.0" ixz="-0.0" iyy="4e-06" iyz="-0.0" izz="4e-06"/></inertial><visual><origin rpy="0 0 0" xyz="-0.082299 -0.0 -0.0"/><geometry><mesh filename="package://yilansimu_description/meshes/vagon_3_1.stl" scale="0.001 0.001 0.001"/></geometry><material name="silver"/></visual><collision><origin rpy="0 0 0" xyz="-0.082299 -0.0 -0.0"/><geometry><mesh filename="package://yilansimu_description/meshes/vagon_3_1.stl" scale="0.001 0.001 0.001"/></geometry></collision></link><link name="vagon_4_1"><inertial><origin rpy="0 0 0" xyz="0.018534672955795556 2.2477804815385055e-08 1.0179807043573117e-08"/><mass value="0.008294307256815433"/><inertia ixx="1e-06" ixy="-0.0" ixz="-0.0" iyy="4e-06" iyz="-0.0" izz="4e-06"/></inertial><visual><origin rpy="0 0 0" xyz="-0.145306 -0.0 -0.0"/><geometry><mesh filename="package://yilansimu_description/meshes/vagon_4_1.stl" scale="0.001 0.001 0.001"/></geometry><material name="silver"/></visual><collision><origin rpy="0 0 0" xyz="-0.145306 -0.0 -0.0"/><geometry><mesh filename="package://yilansimu_description/meshes/vagon_4_1.stl" scale="0.001 0.001 0.001"/></geometry></collision></link><link name="vagon_5_1"><inertial><origin rpy="0 0 0" xyz="0.01642845287141645 -5.974834763900499e-18 -7.169801716680599e-18"/><mass value="0.007878620598601473"/><inertia ixx="1e-06" ixy="-0.0" ixz="0.0" iyy="3e-06" iyz="-0.0" izz="3e-06"/></inertial><visual><origin rpy="0 0 0" xyz="-0.208313 -0.0 -0.0"/><geometry><mesh filename="package://yilansimu_description/meshes/vagon_5_1.stl" scale="0.001 0.001 0.001"/></geometry><material name="silver"/></visual><collision><origin rpy="0 0 0" xyz="-0.208313 -0.0 -0.0"/><geometry><mesh filename="package://yilansimu_description/meshes/vagon_5_1.stl" scale="0.001 0.001 0.001"/></geometry></collision></link><joint name="Revolute 30" type="revolute"><origin rpy="0 0 0" xyz="0.019292 0.0 0.0"/><parent link="base_link"/><child link="vagon_2_1"/><axis xyz="0.0 0.0 1.0"/><limit effort="100" lower="-1.396263" upper="1.396263" velocity="100"/></joint><joint name="Revolute 31" type="revolute"><origin rpy="0 0 0" xyz="0.063007 0.0 0.0"/><parent link="vagon_2_1"/><child link="vagon_3_1"/><axis xyz="0.0 0.0 1.0"/><limit effort="100" lower="-1.396263" upper="1.396263" velocity="100"/></joint><joint name="Revolute 32" type="revolute"><origin rpy="0 0 0" xyz="0.063007 0.0 0.0"/><parent link="vagon_3_1"/><child link="vagon_4_1"/><axis xyz="0.0 0.0 1.0"/><limit effort="100" lower="-1.396263" upper="1.396263" velocity="100"/></joint><joint name="Revolute 33" type="revolute"><origin rpy="0 0 0" xyz="0.063007 0.0 0.0"/><parent link="vagon_4_1"/><child link="vagon_5_1"/><axis xyz="0.0 0.0 1.0"/><limit effort="100" lower="-1.396263" upper="1.396263" velocity="100"/></joint></robot>